Workbook

Sheet Sheet1
O2: No-show rate | P2: =1% -> 0.01 | Q2: 0.03 | R2: 0.05
A4: Sailing | B4: Cabin Type | C4: Fare Class | D4: Capacity (cabins) | E4: Price ($/cabin) | F4: Expected Demand | G4: Overbook Cap | H4: Comp / Guest ($) | I4: Decision booking | J4: Max Allowed Bookings (Cap+OB) | K4: Revenue ($) | L4: overbooking compensation | M4: Net Row Profit ($) | O4: Objective | P4: =SUM(M5:M346) -> 31234927
A5: S1 | B5: Balcony | C5: Early | D5: 1088 | E5: 897 | F5: 434 | G5: 33 | H5: 500 | I5: 412 | J5: =D5+G5 -> 1121 | K5: =I5*E5 -> 369564 | L5: =(1-$Q$2)*(E5+H5)*I351 -> 44717.97 | M5: =K5-L5 -> 324846.03
A6: S1 | B6: Balcony | C6: Premium | D6: 1088 | E6: 1177 | F6: 286 | G6: 33 | H6: 500 | I6: 286 | J6: =D6+G6 -> 1121 | K6: =I6*E6 -> 336622 | L6: =(1-$Q$2)*(E6+H6)*I352 -> 9760.14 | M6: =K6-L6 -> 326861.86
A7: S1 | B7: Balcony | C7: Standard | D7: 1088 | E7: 997 | F7: 423 | G7: 33 | H7: 500 | I7: 423 | J7: =D7+G7 -> 1121 | K7: =I7*E7 -> 421731 | L7: =(1-$Q$2)*(E7+H7)*I353 -> 0 | M7: =K7-L7 -> 421731 | O7: <-- This is OBS1Balcony
A8: S1 | B8: Club Balcony | C8: Early | D8: 308 | E8: 1097 | F8: 119 | G8: 8 | H8: 700 | I8: 119 | J8: =D8+G8 -> 316 | K8: =I8*E8 -> 130543 | L8: =(1-$Q$2)*(E8+H8)*I354 -> 0 | M8: =K8-L8 -> 130543
A9: S1 | B9: Club Balcony | C9: Premium | D9: 308 | E9: 1438 | F9: 79 | G9: 8 | H9: 700 | I9: 79 | J9: =D9+G9 -> 316 | K9: =I9*E9 -> 113602 | L9: =(1-$Q$2)*(E9+H9)*I355 -> 0 | M9: =K9-L9 -> 113602
A10: S1 | B10: Club Balcony | C10: Standard | D10: 308 | E10: 1219 | F10: 116 | G10: 8 | H10: 700 | I10: 116 | J10: =D10+G10 -> 316 | K10: =I10*E10 -> 141404 | L10: =(1-$Q$2)*(E10+H10)*I356 -> 0 | M10: =K10-L10 -> 141404 | O10: I5 + I6 + i7 <= 1121
A11: S1 | B11: Haven | C11: Early | D11: 80 | E11: 5185 | F11: 27 | G11: 1 | H11: 2500 | I11: 27 | J11: =D11+G11 -> 81 | K11: =I11*E11 -> 139995 | L11: =(1-$Q$2)*(E11+H11)*I357 -> 0 | M11: =K11-L11 -> 139995 | O11: I5 + I6 + I7 <= 1088 + OBS1Balcony
A12: S1 | B12: Haven | C12: Premium | D12: 80 | E12: 6799 | F12: 18 | G12: 1 | H12: 2500 | I12: 18 | J12: =D12+G12 -> 81 | K12: =I12*E12 -> 122382 | L12: =(1-$Q$2)*(E12+H12)*I358 -> 0 | M12: =K12-L12 -> 122382
A13: S1 | B13: Haven | C13: Standard | D13: 80 | E13: 5762 | F13: 26 | G13: 1 | H13: 2500 | I13: 26 | J13: =D13+G13 -> 81 | K13: =I13*E13 -> 149812 | L13: =(1-$Q$2)*(E13+H13)*I359 -> 0 | M13: =K13-L13 -> 149812 | O13: OBS1Balcony = how many balcony cabins in Sailing 1 were overbooked
A14: S1 | B14: Inside | C14: Early | D14: 374 | E14: 519 | F14: 146 | G14: 11 | H14: 250 | I14: 135 | J14: =D14+G14 -> 385 | K14: =I14*E14 -> 70065 | L14: =(1-$Q$2)*(E14+H14)*I360 -> 7459.3 | M14: =K14-L14 -> 62605.7
A15: S1 | B15: Inside | C15: Premium | D15: 374 | E15: 680 | F15: 96 | G15: 11 | H15: 250 | I15: 96 | J15: =D15+G15 -> 385 | K15: =I15*E15 -> 65280 | L15: =(1-$Q$2)*(E15+H15)*I361 -> 0 | M15: =K15-L15 -> 65280
A16: S1 | B16: Inside | C16: Standard | D16: 374 | E16: 576 | F16: 143 | G16: 11 | H16: 250 | I16: 143 | J16: =D16+G16 -> 385 | K16: =I16*E16 -> 82368 | L16: =(1-$Q$2)*(E16+H16)*I362 -> 0 | M16: =K16-L16 -> 82368
A17: S1 | B17: Oceanview | C17: Early | D17: 111 | E17: 698 | F17: 40 | G17: 3 | H17: 350 | I17: 40 | J17: =D17+G17 -> 114 | K17: =I17*E17 -> 27920 | L17: =(1-$Q$2)*(E17+H17)*I363 -> 11182.16 | M17: =K17-L17 -> 16737.84
A18: S1 | B18: Oceanview | C18: Premium | D18: 111 | E18: 915 | F18: 27 | G18: 3 | H18: 350 | I18: 27 | J18: =D18+G18 -> 114 | K18: =I18*E18 -> 24705 | L18: =(1-$Q$2)*(E18+H18)*I364 -> 3681.15 | M18: =K18-L18 -> 21023.85
A19: S1 | B19: Oceanview | C19: Standard | D19: 111 | E19: 776 | F19: 39 | G19: 3 | H19: 350 | I19: 39 | J19: =D19+G19 -> 114 | K19: =I19*E19 -> 30264 | L19: =(1-$Q$2)*(E19+H19)*I365 -> 0 | M19: =K19-L19 -> 30264
A20: S1 | B20: Studio | C20: Early | D20: 82 | E20: 558 | F20: 28 | G20: 2 | H20: 220 | I20: 28 | J20: =D20+G20 -> 84 | K20: =I20*E20 -> 15624 | L20: =(1-$Q$2)*(E20+H20)*I366 -> 9055.92 | M20: =K20-L20 -> 6568.08
A21: S1 | B21: Studio | C21: Premium | D21: 82 | E21: 732 | F21: 18 | G21: 2 | H21: 220 | I21: 18 | J21: =D21+G21 -> 84 | K21: =I21*E21 -> 13176 | L21: =(1-$Q$2)*(E21+H21)*I367 -> 0 | M21: =K21-L21 -> 13176
A22: S1 | B22: Studio | C22: Standard | D22: 82 | E22: 620 | F22: 27 | G22: 2 | H22: 220 | I22: 27 | J22: =D22+G22 -> 84 | K22: =I22*E22 -> 16740 | L22: =(1-$Q$2)*(E22+H22)*I368 -> 0 | M22: =K22-L22 -> 16740
A23: S10 | B23: Balcony | C23: Early | D23: 1048 | E23: 893 | F23: 418 | G23: 31 | H23: 500 | I23: 366 | J23: =D23+G23 -> 1079 | K23: =I23*E23 -> 326838 | L23: =(1-$Q$2)*(E23+H23)*I369 -> 37833.88 | M23: =K23-L23 -> 289004.12
A24: S10 | B24: Balcony | C24: Premium | D24: 1048 | E24: 1170 | F24: 275 | G24: 31 | H24: 500 | I24: 275 | J24: =D24+G24 -> 1079 | K24: =I24*E24 -> 321750 | L24: =(1-$Q$2)*(E24+H24)*I370 -> 1619.9 | M24: =K24-L24 -> 320130.1
A25: S10 | B25: Balcony | C25: Standard | D25: 1048 | E25: 992 | F25: 407 | G25: 31 | H25: 500 | I25: 407 | J25: =D25+G25 -> 1079 | K25: =I25*E25 -> 403744 | L25: =(1-$Q$2)*(E25+H25)*I371 -> 0 | M25: =K25-L25 -> 403744
... A119: S15 | B119: Suite | C119: Early | D119: 18 | E119: 2520 | F119: 6 | G119: 0 | H119: 1300 | I119: 6 | J119: =D119+G119 -> 18 | K119: =I119*E119 -> 15120 | L119: =(1-$Q$2)*(E119+H119)*I465 -> 0 | M119: =K119-L119 -> 15120
A120: S15 | B120: Suite | C120: Premium | D120: 18 | E120: 3304 | F120: 4 | G120: 0 | H120: 1300 | I120: 4 | J120: =D120+G120 -> 18 | K120: =I120*E120 -> 13216 | L120: =(1-$Q$2)*(E120+H120)*Sheet2!I1 -> 0 | M120: =K120-L120 -> 13216
A121: S15 | B121: Suite | C121: Standard | D121: 18 | E121: 2800 | F121: 6 | G121: 0 | H121: 1300 | I121: 6 | J121: =D121+G121 -> 18 | K121: =I121*E121 -> 16800 | L121: =(1-$Q$2)*(E121+H121)*Sheet2!I2 -> 0 | M121: =K121-L121 -> 16800
A122: S16 | B122: Balcony | C122: Early | D122: 368 | E122: 815 | F122: 147 | G122: 11 | H122: 500 | I122: 128 | J122: =D122+G122 -> 379 | K122: =I122*E122 -> 104320 | L122: =(1-$Q$2)*(E122+H122)*Sheet2!I3 -> 0 | M122: =K122-L122 -> 104320
A123: S16 | B123: Balcony | C123: Premium | D123: 368 | E123: 1068 | F123: 97 | G123: 11 | H123: 500 | I123: 97 | J123: =D123+G123 -> 379 | K123: =I123*E123 -> 103596 | L123: =(1-$Q$2)*(E123+H123)*Sheet2!I4 -> 0 | M123: =K123-L123 -> 103596
A124: S16 | B124: Balcony | C124: Standard | D124: 368 | E124: 905 | F124: 143 | G124: 11 | H124: 500 | I124: 143 | J124: =D124+G124 -> 379 | K124: =I124*E124 -> 129415 | L124: =(1-$Q$2)*(E124+H124)*Sheet2!I5 -> 0 | M124: =K124-L124 -> 129415
A125: S16 | B125: Club Balcony | C125: Early | D125: 107 | E125: 996 | F125: 41 | G125: 3 | H125: 700 | I125: 40 | J125: =D125+G125 -> 110 | K125: =I125*E125 -> 39840 | L125: =(1-$Q$2)*(E125+H125)*Sheet2!I6 -> 0 | M125: =K125-L125 -> 39840
A126: S16 | B126: Club Balcony | C126: Premium | D126: 107 | E126: 1306 | F126: 27 | G126: 3 | H126: 700 | I126: 27 | J126: =D126+G126 -> 110 | K126: =I126*E126 -> 35262 | L126: =(1-$Q$2)*(E126+H126)*Sheet2!I7 -> 0 | M126: =K126-L126 -> 35262
A127: S16 | B127: Club Balcony | C127: Standard | D127: 107 | E127: 1107 | F127: 40 | G127: 3 | H127: 700 | I127: 40 | J127: =D127+G127 -> 110 | K127: =I127*E127 -> 44280 | L127: =(1-$Q$2)*(E127+H127)*Sheet2!I8 -> 0 | M127: =K127-L127 -> 44280
A128: S16 | B128: Inside | C128: Early | D128: 385 | E128: 471 | F128: 151 | G128: 12 | H128: 250 | I128: 139 | J128: =D128+G128 -> 397 | K128: =I128*E128 -> 65469 | L128: =(1-$Q$2)*(E128+H128)*Sheet2!I9 -> 0 | M128: =K128-L128 -> 65469
A129: S16 | B129: Inside | C129: Premium | D129: 385 | E129: 617 | F129: 99 | G129: 12 | H129: 250 | I129: 99 | J129: =D129+G129 -> 397 | K129: =I129*E129 -> 61083 | L129: =(1-$Q$2)*(E129+H129)*Sheet2!I10 -> 0 | M129: =K129-L129 -> 61083
A130: S16 | B130: Inside | C130: Standard | D130: 385 | E130: 523 | F130: 147 | G130: 12 | H130: 250 | I130: 147 | J130: =D130+G130 -> 397 | K130: =I130*E130 -> 76881 | L130: =(1-$Q$2)*(E130+H130)*Sheet2!I11 -> 0 | M130: =K130-L130 -> 76881
A131: S16 | B131: Oceanview | C131: Early | D131: 250 | E131: 634 | F131: 91 | G131: 6 | H131: 350 | I131: 91 | J131: =D131+G131 -> 256 | K131: =I131*E131 -> 57694 | L131: =(1-$Q$2)*(E131+H131)*Sheet2!I12 -> 0 | M131: =K131-L131 -> 57694
... A259: S4 | B259: Studio | C259: Standard | D259: 82 | E259: 624 | F259: 27 | G259: 2 | H259: 220 | I259: 27 | J259: =D259+G259 -> 84 | K259: =I259*E259 -> 16848 | L259: =(1-$Q$2)*(E259+H259)*Sheet2!I140 -> 0 | M259: =K259-L259 -> 16848
A260: S5 | B260: Balcony | C260: Early | D260: 1086 | E260: 859 | F260: 433 | G260: 33 | H260: 500 | I260: 412 | J260: =D260+G260 -> 1119 | K260: =I260*E260 -> 353908 | L260: =(1-$Q$2)*(E260+H260)*I606 -> 0 | M260: =K260-L260 -> 353908
A261: S5 | B261: Balcony | C261: Premium | D261: 1086 | E261: 1126 | F261: 285 | G261: 33 | H261: 500 | I261: 285 | J261: =D261+G261 -> 1119 | K261: =I261*E261 -> 320910 | L261: =(1-$Q$2)*(E261+H261)*I607 -> 0 | M261: =K261-L261 -> 320910
A262: S5 | B262: Balcony | C262: Standard | D262: 1086 | E262: 954 | F262: 422 | G262: 33 | H262: 500 | I262: 422 | J262: =D262+G262 -> 1119 | K262: =I262*E262 -> 402588 | L262: =(1-$Q$2)*(E262+H262)*I608 -> 0 | M262: =K262-L262 -> 402588
...

Sheet Sheet2
A1: Overbooking Constraints: SUM(I_Early:I_Standard) - D ≤ G (Actual OB ≤ OB Cap, per Sailing × Cabin Type)
A2: Sailing | B2: Cabin Type | C2: B_Early (col I) | D2: B_Premium (col I) | E2: B_Standard (col I) | F2: SUM - Capacity (Actual OB) | G2: OB Cap (col G)
A3: S1 | B3: Balcony | C3: =Sheet1!I5 -> 412 | D3: =Sheet1!I6 -> 286 | E3: =Sheet1!I7 -> 423 | F3: =SUM(Sheet1!I5:I7)-Sheet1!D5 -> 33 | G3: =Sheet1!G5 -> 33
A4: S1 | B4: Club Balcony | C4: =Sheet1!I8 -> 119 | D4: =Sheet1!I9 -> 79 | E4: =Sheet1!I10 -> 116 | F4: =SUM(Sheet1!I8:I10)-Sheet1!D8 -> 6 | G4: =Sheet1!G8 -> 8
A5: S1 | B5: Haven | C5: =Sheet1!I11 -> 27 | D5: =Sheet1!I12 -> 18 | E5: =Sheet1!I13 -> 26 | F5: =SUM(Sheet1!I11:I13)-Sheet1!D11 -> -9 | G5: =Sheet1!G11 -> 1
A6: S1 | B6: Inside | C6: =Sheet1!I14 -> 135 | D6: =Sheet1!I15 -> 96 | E6: =Sheet1!I16 -> 143 | F6: =SUM(Sheet1!I14:I16)-Sheet1!D14 -> 0 | G6: =Sheet1!G14 -> 11
A7: S1 | B7: Oceanview | C7: =Sheet1!I17 -> 40 | D7: =Sheet1!I18 -> 27 | E7: =Sheet1!I19 -> 39 | F7: =SUM(Sheet1!I17:I19)-Sheet1!D17 -> -5 | G7: =Sheet1!G17 -> 3
A8: S1 | B8: Studio | C8: =Sheet1!I20 -> 28 | D8: =Sheet1!I21 -> 18 | E8: =Sheet1!I22 -> 27 | F8: =SUM(Sheet1!I20:I22)-Sheet1!D20 -> -9 | G8: =Sheet1!G20 -> 2
A9: S10 | B9: Balcony | C9: =Sheet1!I23 -> 366 | D9: =Sheet1!I24 -> 275 | E9: =Sheet1!I25 -> 407 | F9: =SUM(Sheet1!I23:I25)-Sheet1!D23 -> 0 | G9: =Sheet1!G23 -> 31
A10: S10 | B10: Club Balcony | C10: =Sheet1!I26 -> 96 | D10: =Sheet1!I27 -> 66 | E10: =Sheet1!I28 -> 98 | F10: =SUM(Sheet1!I26:I28)-Sheet1!D26 -> 0 | G10: =Sheet1!G26 -> 6
A11: S10 | B11: Haven | C11: =Sheet1!I29 -> 39 | D11: =Sheet1!I30 -> 26 | E11: =Sheet1!I31 -> 38 | F11: =SUM(Sheet1!I29:I31)-Sheet1!D29 -> -15 | G11: =Sheet1!G29 -> 1
A12: S10 | B12: Inside | C12: =Sheet1!I32 -> 129 | D12: =Sheet1!I33 -> 85 | E12: =Sheet1!I34 -> 126 | F12: =SUM(Sheet1!I32:I34)-Sheet1!D32 -> 10 | G12: =Sheet1!G32 -> 10
A13: S10 | B13: Oceanview | C13: =Sheet1!I35 -> 40 | D13: =Sheet1!I36 -> 27 | E13: =Sheet1!I37 -> 39 | F13: =SUM(Sheet1!I35:I37)-Sheet1!D35 -> -5 | G13: =Sheet1!G35 -> 3
A14: S10 | B14: Suite | C14: =Sheet1!I38 -> 21 | D14: =Sheet1!I39 -> 14 | E14: =Sheet1!I40 -> 20 | F14: =SUM(Sheet1!I38:I40)-Sheet1!D38 -> -4 | G14: =Sheet1!G38 -> 1
A15: S11 | B15: Balcony | C15: =Sheet1!I41 -> 137 | D15: =Sheet1!I42 -> 94 | E15: =Sheet1!I43 -> 140 | F15: =SUM(Sheet1!I41:I43)-Sheet1!D41 -> 11 | G15: =Sheet1!G41 -> 11
A16: S11 | B16: Club Balcony | C16: =Sheet1!I44 -> 52 | D16: =Sheet1!I45 -> 34 | E16: =Sheet1!I46 -> 51 | F16: =SUM(Sheet1!I44:I46)-Sheet1!D44 -> 3 | G16: =Sheet1!G44 -> 3
A17: S11 | B17: Haven | C17: =Sheet1!I47 -> 6 | D17: =Sheet1!I48 -> 4 | E17: =Sheet1!I49 -> 6 | F17: =SUM(Sheet1!I47:I49)-Sheet1!D47 -> -2 | G17: =Sheet1!G47 -> 0
A18: S11 | B18: Inside | C18: =Sheet1!I50 -> 159 | D18: =Sheet1!I51 -> 104 | E18: =Sheet1!I52 -> 154 | F18: =SUM(Sheet1!I50:I52)-Sheet1!D50 -> 12 | G18: =Sheet1!G50 -> 12
A19: S11 | B19: Oceanview | C19: =Sheet1!I53 -> 89 | D19: =Sheet1!I54 -> 58 | E19: =Sheet1!I55 -> 86 | F19: =SUM(Sheet1!I53:I55)-Sheet1!D53 -> -10 | G19: =Sheet1!G53 -> 6
A20: S11 | B20: Suite | C20: =Sheet1!I56 -> 10 | D20: =Sheet1!I57 -> 7 | E20: =Sheet1!I58 -> 10 | F20: =SUM(Sheet1!I56:I58)-Sheet1!D56 -> -3 | G20: =Sheet1!G56 -> 0
A21: S12 | B21: Balcony | C21: =Sheet1!I59 -> 358 | D21: =Sheet1!I60 -> 248 | E21: =Sheet1!I61 -> 368 | F21: =SUM(Sheet1!I59:I61)-Sheet1!D59 -> 28 | G21: =Sheet1!G59 -> 28
A22: S12 | B22: Club Balcony | C22: =Sheet1!I62 -> 19 | D22: =Sheet1!I63 -> 12 | E22: =Sheet1!I64 -> 18 | F22: =SUM(Sheet1!I62:I64)-Sheet1!D62 -> 1 | G22: =Sheet1!G62 -> 1
A23: S12 | B23: Haven | C23: =Sheet1!I65 -> 36 | D23: =Sheet1!I66 -> 24 | E23: =Sheet1!I67 -> 35 | F23: =SUM(Sheet1!I65:I67)-Sheet1!D65 -> -12 | G23: =Sheet1!G65 -> 1
A24: S12 | B24: Inside | C24: =Sheet1!I68 -> 98 | D24: =Sheet1!I69 -> 70 | E24: =Sheet1!I70 -> 104 | F24: =SUM(Sheet1!I68:I70)-Sheet1!D68 -> 0 | G24: =Sheet1!G68 -> 8
A25: S12 | B25: Oceanview | C25: =Sheet1!I71 -> 45 | D25: =Sheet1!I72 -> 30 | E25: =Sheet1!I73 -> 44 | F25: =SUM(Sheet1!I71:I73)-Sheet1!D71 -> -5 | G25: =Sheet1!G71 -> 3
A26: S12 | B26: Studio | C26: =Sheet1!I74 -> 25 | D26: =Sheet1!I75 -> 16 | E26: =Sheet1!I76 -> 24 | F26: =SUM(Sheet1!I74:I76)-Sheet1!D74 -> -8 | G26: =Sheet1!G74 -> 1
A27: S12 | B27: Suite | C27: =Sheet1!I77 -> 13 | D27: =Sheet1!I78 -> 8 | E27: =Sheet1!I79 -> 12 | F27: =SUM(Sheet1!I77:I79)-Sheet1!D77 -> -3 | G27: =Sheet1!G77 -> 1
A28: S13 | B28: Balcony | C28: =Sheet1!I80 -> 126 | D28: =Sheet1!I81 -> 94 | E28: =Sheet1!I82 -> 140 | F28: =SUM(Sheet1!I80:I82)-Sheet1!D80 -> 0 | G28: =Sheet1!G80 -> 11
A29: S13 | B29: Club Balcony | C29: =Sheet1!I83 -> 49 | D29: =Sheet1!I84 -> 34 | E29: =Sheet1!I85 -> 51 | F29: =SUM(Sheet1!I83:I85)-Sheet1!D83 -> 0 | G29: =Sheet1!G83 -> 3
A30: S13 | B30: Haven | C30: =Sheet1!I86 -> 6 | D30: =Sheet1!I87 -> 4 | E30: =Sheet1!I88 -> 6 | F30: =SUM(Sheet1!I86:I88)-Sheet1!D86 -> -2 | G30: =Sheet1!G86 -> 0
A31: S13 | B31: Inside | C31: =Sheet1!I89 -> 161 | D31: =Sheet1!I90 -> 106 | E31: =Sheet1!I91 -> 157 | F31: =SUM(Sheet1!I89:I91)-Sheet1!D89 -> 12 | G31: =Sheet1!G89 -> 12
A32: S13 | B32: Oceanview | C32: =Sheet1!I92 -> 89 | D32: =Sheet1!I93 -> 58 | E32: =Sheet1!I94 -> 86 | F32: =SUM(Sheet1!I92:I94)-Sheet1!D92 -> -10 | G32: =Sheet1!G92 -> 6
A33: S13 | B33: Suite | C33: =Sheet1!I95 -> 10 | D33: =Sheet1!I96 -> 7 | E33: =Sheet1!I97 -> 10 | F33: =SUM(Sheet1!I95:I97)-Sheet1!D95 -> -3 | G33: =Sheet1!G95 -> 0
A34: S14 | B34: Balcony | C34: =Sheet1!I98 -> 93 | D34: =Sheet1!I99 -> 64 | E34: =Sheet1!I100 -> 95 | F34: =SUM(Sheet1!I98:I100)-Sheet1!D98 -> 7 | G34: =Sheet1!G98 -> 7
A35: S14 | B35: Inside | C35: =Sheet1!I101 -> 156 | D35: =Sheet1!I102 -> 110 | E35: =Sheet1!I103 -> 163 | F35: =SUM(Sheet1!I101:I103)-Sheet1!D101 -> 0 | G35: =Sheet1!G101 -> 13
A36: S14 | B36: Oceanview | C36: =Sheet1!I104 -> 114 | D36: =Sheet1!I105 -> 75 | E36: =Sheet1!I106 -> 111 | F36: =SUM(Sheet1!I104:I106)-Sheet1!D104 -> -13 | G36: =Sheet1!G104 -> 8
A37: S14 | B37: Suite | C37: =Sheet1!I107 -> 5 | D37: =Sheet1!I108 -> 3 | E37: =Sheet1!I109 -> 5 | F37: =SUM(Sheet1!I107:I109)-Sheet1!D107 -> -2 | G37: =Sheet1!G107 -> 0
A38: S15 | B38: Balcony | C38: =Sheet1!I110 -> 136 | D38: =Sheet1!I111 -> 102 | E38: =Sheet1!I112 -> 152 | F38: =SUM(Sheet1!I110:I112)-Sheet1!D110 -> 0 | G38: =Sheet1!G110 -> 12
A39: S15 | B39: Inside | C39: =Sheet1!I113 -> 143 | D39: =Sheet1!I114 -> 101 | E39: =Sheet1!I115 -> 150 | F39: =SUM(Sheet1!I113:I115)-Sheet1!D113 -> 0 | G39: =Sheet1!G113 -> 12
A40: S15 | B40: Oceanview | C40: =Sheet1!I116 -> 81 | D40: =Sheet1!I117 -> 54 | E40: =Sheet1!I118 -> 79 | F40: =SUM(Sheet1!I116:I118)-Sheet1!D116 -> -9 | G40: =Sheet1!G116 -> 6
...
